Workbook

Sheet PT320
A1: PT 320 - Materialidade (R$ mil; DFP 2025 consolidada)
A2: Preparador: matricula 180109791 | Data: 25/10/2026 | Revisao: ____ (campo em branco, sem revisao de terceiros) | Azul = entrada/dado; preto = formula
A4: Base de referencia | B4: Valor 2025 | C4: Percentual | D4: Fonte / justificativa | E4: Resultado (R$ mil)
A5: Lucro antes dos tributos (LAIR) | B5: 601586 | C5: 0.05 | D5: DFP p.23 - base escolhida: resultado recorrente e positivo; usuarios (acionistas Novo Mercado) focam lucro | E5: =B5*C5 -> 30079.3
A6: Receita liquida | B6: 1498822 | C6: 0.01 | D6: DFP p.23 - alternativa | E6: =B6*C6 -> 14988.22
A7: Ativo total | B7: 7196637 | C7: 0.005 | D7: DFP p.20 - alternativa (empresa intensiva em ativos) | E7: =B7*C7 -> 35983.185
A8: Patrimonio liquido | B8: 5119897 | C8: 0.01 | D8: DFP p.22 - alternativa | E8: =B8*C8 -> 51198.97
A10: Faixa das alternativas (minimo / maximo) | B10: =MIN(E5:E8) -> 14988.22 | C10: =MAX(E5:E8) -> 51198.97
A12: MATERIALIDADE GLOBAL (5% do LAIR, arredondada) | B12: =ROUND(E5,0) -> 30079 | D12: Dentro da faixa das alternativas (B10:C10) - teste de razoabilidade: | E12: =IF(AND(B12>=B10,B12<=C10),"RAZOAVEL","REVISAR") -> RAZOAVEL
A13: Percentual da materialidade para execucao (PM) | B13: 0.65 | D13: 65% (faixa usual 50-75%): auditoria inicial (PT 510), estimativa-chave de POC (PAA do relatorio, p.70) e partes relacionadas com risco elevado
A14: MATERIALIDADE PARA EXECUCAO (PM) | B14: =ROUND(B12*B13,0) -> 19551
A15: Percentual do limite de distorcoes claramente triviais | B15: 0.05
A16: LIMITE DE DISTORCOES TRIVIAIS | B16: =ROUND(B12*B15,0) -> 1504
A18: Materialidades especificas (NBC TA 320 item 10)
A19: Partes relacionadas e remuneracao da administracao - % da global | B19: 0.1
A20: Materialidade especifica - partes relacionadas / honorarios | B20: =ROUND(B12*B19,0) -> 3008 | D20: Usuarios sao sensiveis a transacoes com partes relacionadas (nota 15, p.59) e a honorarios (nota 21, p.63)
A22: Revisao: reavaliar B12 se o LAIR final divergir do usado em mais de 10% (NBC TA 320 itens 12-13). Nenhuma revisao ocorreu (didatico).

Sheet PT520
A1: PT 520 - Procedimentos analiticos (R$ mil)
A2: Preparador: matricula 180109791 | Data: 25/10/2026 | Revisao: ____ (campo em branco, sem revisao de terceiros) | Azul = entrada/dado; preto = formula
A4: Limite de investigacao = 25% da PM (precisao da expectativa) | B4: =0.25*PT320!B14 -> 4887.75 | E4: Diferencas acima do limite exigem investigacao
A6: A. Encargos financeiros capitalizados em estoques (nota 7, p.51) | B6: 2025 | C6: 2024 | E6: Fonte
A7: Saldo inicial | B7: 111323 | C7: 80977 | E7: DFP p.51, movimentacao dos encargos
A8: (+) Encargos capitalizados no exercicio | B8: 124065 | C8: 60088
A9: (-) Baixa de encargos no exercicio | B9: -37935 | C9: -29742
A10: Saldo final recalculado | B10: =SUM(B7:B9) -> 197453 | C10: =SUM(C7:C9) -> 111323
A11: Saldo final divulgado | B11: 197453 | C11: 111323
A12: Diferenca (recalculado - divulgado) | B12: =B10-B11 -> 0 | C12: =C10-C11 -> 0
A14: B. Expectativa da baixa de encargos (proporcional ao saldo inicial) | B14: 2025 | C14: 2024
A15: Razao baixa/saldo inicial em 2024 | C15: =-C9/C7 -> 0.36728948
A16: Baixa esperada 2025 = saldo inicial 2025 x razao 2024 | B16: =B7*C15 -> 40887.766
A17: Baixa registrada 2025 | B17: =-B9 -> 37935
A18: Diferenca | B18: =B17-B16 -> -2952.7665
A19: Conclusao | B19: =IF(ABS(B18)>$B$4,"INVESTIGAR","DENTRO DO LIMITE") -> DENTRO DO LIMITE
A21: C. Taxa de capitalizacao de juros (notas 11 e 12, pp.55-56) | B21: 2025 | C21: 2024
A22: Juros incorridos - emprestimos e financiamentos | B22: 81254 | C22: 57435
A23: Juros incorridos - debentures e CRI | B23: 96628 | C23: 35994
A24: Total de juros incorridos | B24: =B22+B23 -> 177882 | C24: =C22+C23 -> 93429
A25: Encargos capitalizados no exercicio | B25: =B8 -> 124065 | C25: =C8 -> 60088
A26: Razao capitalizado / incorrido | B26: =B25/B24 -> 0.69745674 | C26: =C25/C24 -> 0.64314078
A27: Capitalizacao esperada 2025 = juros 2025 x razao 2024 | B27: =B24*C26 -> 114403.17
A28: Diferenca (registrado - esperado) | B28: =B25-B27 -> 9661.8316 | E28: Investigacao exige dados internos (ativos qualificaveis por empreendimento): PLANEJADO
A29: Conclusao | B29: =IF(ABS(B28)>$B$4,"INVESTIGAR","DENTRO DO LIMITE") -> INVESTIGAR
A31: D. Indicadores (consolidado) | B31: 2025 | C31: 2024 | D31: 2023 | E31: Observacao
A32: Margem bruta | B32: =625157/1498822 -> 0.41709889 | C32: =532812/1560541 -> 0.34142775 | D32: =343699/1083172 -> 0.31730787 | E32: Margem +7,6 p.p. em 2025: INVESTIGAR (dados de empreendimento nao publicos)
A33: Estoques totais (circ.+nao circ.) | B33: 3125834 | C33: 3128884 | D33: 3090773
A34: Custo dos imoveis vendidos | B34: 873665 | C34: 1027729 | D34: 739473
A35: Giro dos estoques em dias (estoque/CPV x 365) | B35: =B33/B34*365 -> 1305.9118 | C35: =C33/C34*365 -> 1111.2294 | D35: =D33/D34*365 -> 1525.5894
A36: Contas a receber totais | B36: 1727447 | C36: 1753570 | D36: 1200036
A37: Receita liquida | B37: 1498822 | C37: 1560541 | D37: 1083172
A38: Prazo medio de recebimento em dias (CR/receita x 365) | B38: =B36/B37*365 -> 420.67581 | C38: =C36/C37*365 -> 410.14818 | D38: =D36/D37*365 -> 404.38004
A40: E. Variacao de linhas selecionadas 2025 x 2024 | B40: 2025 | C40: 2024 | D40: Var. % | E40: Investigar?
A41: Outras receitas operacionais (DRE, p.23) | B41: 39857 | C41: -4134 | D41: =IF(C41=0,0,(B41-C41)/ABS(C41)) -> 10.641268 | E41: =IF(ABS(B41-C41)>$B$4,"INVESTIGAR","ok")&" Notas 9(e),(f): ganhos AK14 R$16.641 e Tupi R$29.821 (liquidos) explicam parte - evidencia publica" -> INVESTIGAR Notas 9(e),(f): ganhos AK14 R$16.641 e Tupi R$29.821 (liquidos) explicam parte - evidencia publica
A42: Despesas financeiras (DRE, p.23) | B42: 86036 | C42: 44891 | D42: =IF(C42=0,0,(B42-C42)/ABS(C42)) -> 0.91655343 | E42: =IF(ABS(B42-C42)>$B$4,"INVESTIGAR","ok")&" " -> INVESTIGAR
A43: Receitas financeiras (DRE, p.23) | B43: 245765 | C43: 176919 | D43: =IF(C43=0,0,(B43-C43)/ABS(C43)) -> 0.38913853 | E43: =IF(ABS(B43-C43)>$B$4,"INVESTIGAR","ok")&" " -> INVESTIGAR
A44: Contas a receber vencidas > 120 dias (nota 6, p.50) | B44: 28016 | C44: 13130 | D44: =IF(C44=0,0,(B44-C44)/ABS(C44)) -> 1.1337395 | E44: =IF(ABS(B44-C44)>$B$4,"INVESTIGAR","ok")&" " -> INVESTIGAR
A45: Provisao distratos e creditos (nota 6, p.50) | B45: 24125 | C45: 11062 | D45: =IF(C45=0,0,(B45-C45)/ABS(C45)) -> 1.1808895 | E45: =IF(ABS(B45-C45)>$B$4,"INVESTIGAR","ok")&" " -> INVESTIGAR

Sheet PT530
A1: PT 530 - Amostragem MUS sobre a base SINTETICA (R$)
A2: Preparador: matricula 180109791 | Data: 25/10/2026 | Revisao: ____ (campo em branco, sem revisao de terceiros) | Azul = entrada/dado; preto = formula
A4: Parametro | B4: Valor | C4: Observacao | I4: Evidencia documental SIMULADA: valor_documento_simulado vem do registro de erros inseridos (oraculo), nao de documento real.
A5: Distorcao toleravel (= PM x 1.000, R$) | B5: =PT320!B14*1000 -> 19551000
A6: Fator de confianca (risco de aceitacao incorreta 5%, 0 erros) | B6: 3
A7: Intervalo de amostragem (R$) | B7: =B5/B6 -> 6517000
A8: Populacao: soma dos lancamentos positivos (R$) | B8: 3.1513476e+09
A9: Tamanho estimado da amostra | B9: =ROUNDUP(B8/B7,0) -> 484
A10: Inicio aleatorio (semente 180109792) | B10: 5181876
A11: Itens-chave (valor >= intervalo) | B11: 0
A12: Itens selecionados (script) | B12: =COUNTA(A32:A600) -> 483
A14: Avaliacao (Stringer, Poisson 5%) | B14: taint | C14: Incremento | D14: Contribuicao (R$)
A15: Precisao basica = fator x intervalo | D15: =B6*B7 -> 19551000
A16: Excecao residual 1 (id 416030) | B16: 0.2136969 | C16: 1.75 | D16: =B16*C16*$B$7 -> 2437159.7
A17: Excecao residual 2 (id 342042) | B17: 0.21190917 | C17: 1.55 | D17: =B17*C17*$B$7 -> 2140568.7
A18: Excecao residual 3 (id 445241) | B18: 0.20933957 | C18: 1.46 | D18: =B18*C18*$B$7 -> 1991828.3
A19: Excecao residual 4 (id 452088) | B19: 0.20496276 | C19: 1.4 | D19: =B19*C19*$B$7 -> 1870039.2
A20: Excecao residual 5 (id 446629) | B20: 0.11611967 | C20: 1.36 | D20: =B20*C20*$B$7 -> 1029182.5
A21: Excecao residual 6 (id 432949) | B21: 0.092160534 | C21: 1.33 | D21: =B21*C21*$B$7 -> 798811.57
A22: LIMITE SUPERIOR DA DISTORCAO (Stringer) | D22: =D15+SUM(D16:D21) -> 29818590
A23: Projecao da distorcao (soma taint x intervalo) | D23: =SUMPRODUCT(B16:B21)*B7 -> 6831045
A24: Limite superior x distorcao toleravel | D24: =IF(D22>B5,"EXCEDE PM: ampliar amostra/ajustar","DENTRO DA PM") -> EXCEDE PM: ampliar amostra/ajustar
A25: Limite superior x materialidade global | D25: =IF(D22>PT320!B12*1000,"EXCEDE GLOBAL","ABAIXO DA GLOBAL") -> ABAIXO DA GLOBAL
A31: id_lancamento | B31: valor_rs | C31: valor_documento_simulado | D31: distorcao_rs | E31: tipo_excecao | F31: ja_identificada_100pct | G31: taint
A32: 1530 | B32: 3324.38 | C32: 3324.38 | D32: 0 | F32: =FALSE() -> FALSE | G32: 0
A33: 3518 | B33: 3453.73 | C33: 3453.73 | D33: 0 | F33: =FALSE() -> FALSE | G33: 0
A34: 5476 | B34: 2419.56 | C34: 2419.56 | D34: 0 | F34: =FALSE() -> FALSE | G34: 0
A35: 7531 | B35: 36218.01 | C35: 36218.01 | D35: 0 | F35: =FALSE() -> FALSE | G35: 0
A36: 9388 | B36: 18383.41 | C36: 18383.41 | D36: 0 | F36: =FALSE() -> FALSE | G36: 0
A37: 11381 | B37: 1612.25 | C37: 1612.25 | D37: 0 | F37: =FALSE() -> FALSE | G37: 0
A38: 13434 | B38: 2400.99 | C38: 2400.99 | D38: 0 | F38: =FALSE() -> FALSE | G38: 0
A39: 15424 | B39: 6890.27 | C39: 6890.27 | D39: 0 | F39: =FALSE() -> FALSE | G39: 0
A40: 17522 | B40: 4961.63 | C40: 4961.63 | D40: 0 | F40: =FALSE() -> FALSE | G40: 0
A41: 19666 | B41: 16146.93 | C41: 16146.93 | D41: 0 | F41: =FALSE() -> FALSE | G41: 0
A42: 21677 | B42: 5896.11 | C42: 5896.11 | D42: 0 | F42: =FALSE() -> FALSE | G42: 0
A43: 23718 | B43: 3418.69 | C43: 3418.69 | D43: 0 | F43: =FALSE() -> FALSE | G43: 0
... A250: 313607 | B250: 15136.22 | C250: 15136.22 | D250: 0 | F250: =FALSE() -> FALSE | G250: 0
A251: 314643 | B251: 9592.98 | C251: 9592.98 | D251: 9592.98 | E251: CUSTO_NAO_CAPITALIZAVEL | F251: =TRUE() -> TRUE | G251: 1
A252: 315771 | B252: 7017.6 | C252: 7017.6 | D252: 0 | F252: =FALSE() -> FALSE | G252: 0
A253: 316929 | B253: 20758.1 | C253: 20758.1 | D253: 20758.1 | E253: CORTE | F253: =TRUE() -> TRUE | G253: 1
...

Sheet PT500
A1: PT 500 - Conciliacao da base sintetica com a DFP e verificacoes internas da DFP
A2: Preparador: matricula 180109791 | Data: 25/10/2026 | Revisao: ____ (campo em branco, sem revisao de terceiros) | Azul = entrada/dado; preto = formula
A4: Categoria (nota 7, p.51) | B4: Saldo contabil (R$) | C4: Base sintetica (R$) | D4: Diferenca (R$) | E4: Explicada pelo registro (R$) | F4: Nao explicada (R$)
A5: ADIANTAMENTO_FORNECEDORES | B5: =19513*1000 -> 19513000 | C5: 19919496 | D5: =C5-B5 -> 406495.54 | E5: 406495.54 | F5: =ROUND(D5-E5,2) -> 0
A6: ENCARGOS_FINANCEIROS | B6: =197453*1000 -> 197453000 | C6: 2.0102997e+08 | D6: =C6-B6 -> 3576967.6 | E6: 3576967.6 | F6: =ROUND(D6-E6,2) -> 0
A7: IMOVEIS_CONCLUIDOS | B7: =485897*1000 -> 485897000 | C7: 4.8839491e+08 | D7: =C7-B7 -> 2497906.2 | E7: 2497906.2 | F7: =ROUND(D7-E7,2) -> 0
A8: IMOVEIS_EM_CONSTRUCAO | B8: =1421820*1000 -> 1421820000 | C8: 1.4328294e+09 | D8: =C8-B8 -> 11009371 | E8: 11009371 | F8: =ROUND(D8-E8,2) -> 0
A9: TERRENOS_NOVAS_OBRAS | B9: =1001151*1000 -> 1001151000 | C9: 1.0090098e+09 | D9: =C9-B9 -> 7858818.4 | E9: 7858818.4 | F9: =ROUND(D9-E9,2) -> 0
A10: TOTAL | B10: =SUM(B5:B9) -> 3125834000 | C10: =SUM(C5:C9) -> 3.1511836e+09 | D10: =SUM(D5:D9) -> 25349559 | E10: =SUM(E5:E9) -> 25349559 | F10: =SUM(F5:F9) -> 0
A12: Verificacoes internas da DFP (real) | B12: Valor A | C12: Valor B | D12: Diferenca | E12: Resultado | F12: Fonte
A13: Ativo total = Passivo + PL (consolidado) | B13: 7196637 | C13: =396609+1680131+5119897 -> 7196637 | D13: =B13-C13 -> 0 | E13: =IF(ABS(D13)<=1,"CONFERE (<= R$ 1 mil)","DIVERGE") -> CONFERE (<= R$ 1 mil) | F13: p.20-22
A14: Ativo circulante + nao circulante = ativo total | B14: =3303420+3893217 -> 7196637 | C14: 7196637 | D14: =B14-C14 -> 0 | E14: =IF(ABS(D14)<=1,"CONFERE (<= R$ 1 mil)","DIVERGE") -> CONFERE (<= R$ 1 mil) | F14: p.20
A15: Nota 7 (soma) = estoques circ. + nao circ. | B15: =485897+1421820+1001151+197453+19513 -> 3125834 | C15: =1282510+1843324 -> 3125834 | D15: =B15-C15 -> 0 | E15: =IF(ABS(D15)<=1,"CONFERE (<= R$ 1 mil)","DIVERGE") -> CONFERE (<= R$ 1 mil) | F15: p.51 e p.20
A16: Nota 6 (contas a receber) = circ. + nao circ. no balanco | B16: 1727447 | C16: =439254+1288193 -> 1727447 | D16: =B16-C16 -> 0 | E16: =IF(ABS(D16)<=1,"CONFERE (<= R$ 1 mil)","DIVERGE") -> CONFERE (<= R$ 1 mil) | F16: p.50 e p.20
A17: Nota 12 debentures/CRI = circ. + nao circ. | B17: 1097208 | C17: =35558+1061650 -> 1097208 | D17: =B17-C17 -> 0 | E17: =IF(ABS(D17)<=1,"CONFERE (<= R$ 1 mil)","DIVERGE") -> CONFERE (<= R$ 1 mil) | F17: p.55 e p.21
A18: Nota 11 emprestimos = circ. + nao circ. | B18: 608777 | C18: =113237+495540 -> 608777 | D18: =B18-C18 -> 0 | E18: =IF(ABS(D18)<=1,"CONFERE (<= R$ 1 mil)","DIVERGE") -> CONFERE (<= R$ 1 mil) | F18: p.55 e p.21
A19: PL: capital + reservas de capital + reservas de lucro + nao controladores | B19: 5119897 | C19: =4301053-62711+792204+89351 -> 5119897 | D19: =B19-C19 -> 0 | E19: =IF(ABS(D19)<=1,"CONFERE (<= R$ 1 mil)","DIVERGE") -> CONFERE (<= R$ 1 mil) | F19: p.22
A20: Caixa e equivalentes: balanco x DFC | B20: 66575 | C20: 66574 | D20: =B20-C20 -> 1 | E20: =IF(ABS(D20)<=1,"CONFERE (<= R$ 1 mil)","DIVERGE") -> CONFERE (<= R$ 1 mil) | F20: p.20 e p.27 (diferenca de arredondamento)
A21: Nota 7: encargos - roll forward | B21: 197453 | C21: =111323+124065-37935 -> 197453 | D21: =B21-C21 -> 0 | E21: =IF(ABS(D21)<=1,"CONFERE (<= R$ 1 mil)","DIVERGE") -> CONFERE (<= R$ 1 mil) | F21: p.51
A22: Nota 11: emprestimos - movimentacao (836.309+429.214-670.620-67.380+81.254) | B22: 608777 | C22: =836309+429214-670620-67380+81254 -> 608777 | D22: =B22-C22 -> 0 | E22: =IF(ABS(D22)<=1,"CONFERE (<= R$ 1 mil)","DIVERGE") -> CONFERE (<= R$ 1 mil) | F22: p.55
A23: Nota 12: debentures/CRI - movimentacao (300.073+757.911-59.306+96.628+1.902) | B23: 1097208 | C23: =300073+757911-59306+96628+1902 -> 1097208 | D23: =B23-C23 -> 0 | E23: =IF(ABS(D23)<=1,"CONFERE (<= R$ 1 mil)","DIVERGE") -> CONFERE (<= R$ 1 mil) | F23: p.55
A24: DFC captacoes (6.03.01) x notas 11+12 (429.214+757.911) | B24: 1187114 | C24: =429214+757911 -> 1187125 | D24: =B24-C24 -> -11 | E24: =IF(ABS(D24)<=1,"CONFERE (<= R$ 1 mil)","DIVERGE") -> DIVERGE | F24: p.27, p.55 (dif. R$ 11 mil < trivial)
A25: Imobilizado+intangivel: saldo inicial + adicoes - deprec./amort. = saldo final | B25: =36152+2959+21775-12042 -> 48844 | C25: =45743+3101 -> 48844 | D25: =B25-C25 -> 0 | E25: =IF(ABS(D25)<=1,"CONFERE (<= R$ 1 mil)","DIVERGE") -> CONFERE (<= R$ 1 mil) | F25: p.20, p.26 (supoe ausencia de baixas)
A26: Nota 5: aplicacoes (CDB + fundos + LFs) = balanco | B26: =985389+40021+466557 -> 1491967 | C26: 1491967 | D26: =B26-C26 -> 0 | E26: =IF(ABS(D26)<=1,"CONFERE (<= R$ 1 mil)","DIVERGE") -> CONFERE (<= R$ 1 mil) | F26: p.49 e p.20
A27: Nota 21: remuneracao fixa + variavel = DRE (honorarios) | B27: =13835+6162 -> 19997 | C27: 19997 | D27: =B27-C27 -> 0 | E27: =IF(ABS(D27)<=1,"CONFERE (<= R$ 1 mil)","DIVERGE") -> CONFERE (<= R$ 1 mil) | F27: p.63 e p.23
A28: Nota 14: tributos diferidos = circ. + nao circ. | B28: 85425 | C28: =18097+67328 -> 85425 | D28: =B28-C28 -> 0 | E28: =IF(ABS(D28)<=1,"CONFERE (<= R$ 1 mil)","DIVERGE") -> CONFERE (<= R$ 1 mil) | F28: p.58

Sheet PT450
A1: PT 450 - Mapa de distorcoes (SINTETICAS, inseridas) - avaliacao quantitativa (R$)
A2: Preparador: matricula 180109791 | Data: 25/10/2026 | Revisao: ____ (campo em branco, sem revisao de terceiros) | Azul = entrada/dado; preto = formula
A4: Tipo de erro inserido | B4: Qtde | C4: Efeito na base (R$) | D4: Distorcao potencial (R$) | E4: Status (didatico)
A5: E01_DUPLICIDADE | B5: 180 | C5: 7006799.9 | D5: 7006799.9 | E5: Nao corrigida (proposta de ajuste); detalhe em registro_erros_inseridos.csv
A6: E02_CORTE | B6: 150 | C6: 0 | D6: 6760303.6 | E6: Nao corrigida (proposta de ajuste); detalhe em registro_erros_inseridos.csv
A7: E03_MANUAL_FDS_REDONDO | B7: 60 | C7: 11881725 | D7: 11881725 | E7: Nao corrigida (proposta de ajuste); detalhe em registro_erros_inseridos.csv
A8: E04_CLASSIFICACAO | B8: 120 | C8: 0 | D8: 0 | E8: Nao corrigida (proposta de ajuste); detalhe em registro_erros_inseridos.csv
A9: E05_CUSTO_NAO_CAPITALIZAVEL | B9: 70 | C9: 0 | D9: 1790351.4 | E9: Nao corrigida (proposta de ajuste); detalhe em registro_erros_inseridos.csv
A10: E06_ENCARGO_TAXA | B10: 60 | C10: 3081844.7 | D10: 3081844.7 | E10: Nao corrigida (proposta de ajuste); detalhe em registro_erros_inseridos.csv
A11: E07_UNIDADE_VENDIDA | B11: 110 | C11: 0 | D11: 1911783.1 | E11: Nao corrigida (proposta de ajuste); detalhe em registro_erros_inseridos.csv
A12: E08_FORNECEDOR_INEXISTENTE | B12: 45 | C12: 0 | D12: 2353434.4 | E12: Nao corrigida (proposta de ajuste); detalhe em registro_erros_inseridos.csv
A13: E09_ESTORNO_SEM_REFERENCIA | B13: 50 | C13: -328146.76 | D13: -328146.76 | E13: Nao corrigida (proposta de ajuste); detalhe em registro_erros_inseridos.csv
A14: E10_VALOR_DIVERGENTE | B14: 60 | C14: 3707335.9 | D14: 3707335.9 | E14: Nao corrigida (proposta de ajuste); detalhe em registro_erros_inseridos.csv
A15: TOTAL | B15: =SUM(B5:B14) -> 905 | C15: =SUM(C5:C14) -> 25349559 | D15: =SUM(D5:D14) -> 38165432
A17: Distorcao potencial agregada (R$ mil) | D17: =D15/1000 -> 38165.432
A18: Materialidade global (R$ mil) | D18: =PT320!B12 -> 30079
A19: Materialidade para execucao (R$ mil) | D19: =PT320!B14 -> 19551
A20: Limite de distorcoes triviais (R$ mil) | D20: =PT320!B16 -> 1504
A21: Agregado / global | D21: =D17/D18 -> 1.2688398
A22: Conclusao quantitativa | D22: =IF(D17>D18,"EXCEDE a materialidade global (se fossem reais: ajuste ou modificacao de opiniao)",IF(D17>D19,"Excede a PM; abaixo da global: avaliar qualitativamente","Abaixo da PM")) -> EXCEDE a materialidade global (se fossem reais: ajuste ou modificacao de opiniao)
A24: ATENCAO: distorcoes inseridas em dados sinteticos. Nao representam distorcoes da EZTEC.

Sheet PT540
A1: PT 540 - Sensibilidade da estimativa de custo orcado (POC) - nota 10, p.54 (R$ mil)
A2: Preparador: matricula 180109791 | Data: 25/10/2026 | Revisao: ____ (campo em branco, sem revisao de terceiros) | Azul = entrada/dado; preto = formula
A4: Receita de vendas contratadas (empreend. em construcao) | B4: 2889190
A5: Custo orcado das unidades vendidas | B5: 1819076
A6: Custo de construcao incorrido (sem encargos) | B6: 871239
A7: POC (driver) = incorrido / orcado | B7: =B6/B5 -> 0.4789459 | C7: Divulgado: 47,89%
A8: Receita apropriada (aproximacao = contratada x POC) | B8: =B4*B7 -> 1383765.7 | C8: Divulgada (nota 10): 1.401.728
A10: Cenario: variacao do custo orcado | B10: -10% | C10: -5% | D10: 0% | E10: +5% | F10: +10%
A11: Variacao do orcado | B11: -0.1 | C11: -0.05 | D11: 0 | E11: 0.05 | F11: 0.1
A12: Custo orcado ajustado | B12: =$B$5*(1+B11) -> 1637168.4 | C12: =$B$5*(1+C11) -> 1728122.2 | D12: =$B$5*(1+D11) -> 1819076 | E12: =$B$5*(1+E11) -> 1910029.8 | F12: =$B$5*(1+F11) -> 2000983.6
A13: POC ajustado | B13: =$B$6/B12 -> 0.53216212 | C13: =$B$6/C12 -> 0.50415358 | D13: =$B$6/D12 -> 0.4789459 | E13: =$B$6/E12 -> 0.45613896 | F13: =$B$6/F12 -> 0.43540537
A14: Receita apropriada ajustada | B14: =$B$4*B13 -> 1537517.5 | C14: =$B$4*C13 -> 1456595.5 | D14: =$B$4*D13 -> 1383765.7 | E14: =$B$4*E13 -> 1317872.1 | F14: =$B$4*F13 -> 1257968.8
A15: Efeito na receita/resultado bruto | B15: =B14-$B$8 -> 153751.75 | C15: =C14-$B$8 -> 72829.775 | D15: =D14-$B$8 -> 0 | E15: =E14-$B$8 -> -65893.606 | F15: =F14-$B$8 -> -125796.88
A16: vs. PM | B16: =IF(ABS(B15)>PT320!$B$14,"> PM","<= PM") -> > PM | C16: =IF(ABS(C15)>PT320!$B$14,"> PM","<= PM") -> > PM | D16: =IF(ABS(D15)>PT320!$B$14,"> PM","<= PM") -> <= PM | E16: =IF(ABS(E15)>PT320!$B$14,"> PM","<= PM") -> > PM | F16: =IF(ABS(F15)>PT320!$B$14,"> PM","<= PM") -> > PM
A18: Variacao do orcado que consome a PM (break-even) | B18: =B6/(B7-PT320!B14/B4)/B5-1 -> 0.014331322
A19: Limitacao: aproximacao agregada; o POC real e calculado por unidade/empreendimento (nota 2.16, p.46). Orcado por empreendimento nao e publico: PLANEJADO.

Sheet PT570
A1: PT 570 - Continuidade operacional: liquidez e endividamento (R$ mil; consolidado)
A2: Preparador: matricula 180109791 | Data: 25/10/2026 | Revisao: ____ (campo em branco, sem revisao de terceiros) | Azul = entrada/dado; preto = formula
A4: Item | B4: 2025 | C4: 2024 | D4: 2023 | E4: Fonte
A5: Ativo circulante | B5: 3303420 | C5: 2616102 | D5: 2510852 | E5: DFP p.20
A6: Passivo circulante | B6: 396609 | C6: 382378 | D6: 402620 | E6: DFP p.21
A7: Caixa e equivalentes | B7: 66575 | C7: 71381 | D7: 84186 | E7: DFP p.20
A8: Aplicacoes financeiras | B8: 1491967 | C8: 699051 | D8: 678090 | E8: DFP p.20
A9: Emprestimos, financiamentos e debentures - circulante | B9: 148795 | C9: 85958 | D9: 136471 | E9: DFP p.21
A10: Emprestimos, financiamentos e debentures - nao circulante | B10: 1557190 | C10: 1050424 | D10: 719700 | E10: DFP p.21
A11: Patrimonio liquido | B11: 5119897 | C11: 4883126 | D11: 4705064 | E11: DFP p.22
A12: Caixa liquido das atividades operacionais | B12: 503785 | C12: -28991 | D12: -228599 | E12: DFP p.26
A14: Liquidez corrente | B14: =B5/B6 -> 8.3291605 | C14: =C5/C6 -> 6.8416645 | D14: =D5/D6 -> 6.2362824
A15: Disponibilidades (caixa + aplicacoes) | B15: =B7+B8 -> 1558542 | C15: =C7+C8 -> 770432 | D15: =D7+D8 -> 762276
A16: Liquidez imediata (disponibilidades / passivo circulante) | B16: =B15/B6 -> 3.9296688 | C16: =C15/C6 -> 2.014844 | D16: =D15/D6 -> 1.893289
A17: Divida bruta | B17: =B9+B10 -> 1705985 | C17: =C9+C10 -> 1136382 | D17: =D9+D10 -> 856171
A18: Divida liquida (bruta - disponibilidades) | B18: =B17-B15 -> 147443 | C18: =C17-C15 -> 365950 | D18: =D17-D15 -> 93895
A19: Divida bruta / PL | B19: =B17/B11 -> 0.3332069 | C19: =C17/C11 -> 0.23271609 | D19: =D17/D11 -> 0.18196798
A20: Divida liquida / PL | B20: =B18/B11 -> 0.02879804 | C20: =C18/C11 -> 0.074941748 | D20: =D18/D11 -> 0.019956158
A21: Disponibilidades / divida circulante (cobertura do curto prazo) | B21: =B15/B9 -> 10.474425 | C21: =C15/C9 -> 8.9628889 | D21: =D15/D9 -> 5.5856263
A23: Covenant (nota 12, p.56): (Divida liquida + imoveis a pagar) / PL < 0,80 | B23: Valor | E23: Observacao
A24: Debentures e CRI (liquido de custos) | B24: 1097208
A25: (-) Disponibilidades 2025 | B25: =-B15 -> -1558542
A26: (+) Imoveis a pagar (terrenos a pagar circ. 36.421 + nao circ. 28.027) | B26: =36421+28027 -> 64448
A27: Numerador recomputado (HIPOTESE: exclui financiamentos a producao) | B27: =SUM(B24:B26) -> -396886
A28: Indice recomputado | B28: =B27/B11 -> -0.077518356 | E28: Divulgado: (0,08). Conferencia aproximada; definicao contratual nao acessada
A29: Segundo indice (>1,50): divulgado 13,83 - nao reproduzivel com dados publicos: PLANEJADO (escritura de emissao)
A31: Fluxo: FCO positivo em 2025 apos dois exercicios negativos; captacoes liquidas financiaram investimentos (DFC p.26-27).

Sheet PT505
A1: PT 505 - Controle de circularizacao (DIDATICO: NENHUMA solicitacao enviada)
A2: Preparador: matricula 180109791 | Data: 25/10/2026 | Revisao: ____ (campo em branco, sem revisao de terceiros) | Azul = entrada/dado; preto = formula
A4: Tipo | B4: Saldo a confirmar (DFP) | C4: Valor (R$ mil) | D4: Modelo | E4: Status | F4: Data envio | G4: Tratamento de diferencas / procedimento alternativo
A5: Bancos - aplicacoes financeiras | B5: Nota 5 (p.49) | C5: 1491967 | D5: Modelo A | E5: NAO ENVIADO (didatico) | F5: - | G5: Aplicacoes e saldos em conta; garantias/gravames
A6: Bancos - caixa e equivalentes | B6: Nota 4 (p.49) | C6: 66575 | D6: Modelo A | E6: NAO ENVIADO (didatico) | F6: - | G6: Extratos e conciliacoes bancarias
A7: Credores - emprestimos e financiamentos | B7: Nota 11 (p.55) | C7: 608777 | D7: Modelo A | E7: NAO ENVIADO (didatico) | F7: - | G7: Contratos, extratos de credor, recalculo de juros
A8: Debentures/CRI - agente fiduciario | B8: Nota 12 (p.55) | C8: 1097208 | D8: Modelo A | E8: NAO ENVIADO (didatico) | F8: - | G8: Extrato do agente fiduciario e escrituras
A9: Clientes - contas a receber | B9: Nota 6 (p.50) | C9: 1727447 | D9: Modelo B | E9: NAO ENVIADO (didatico) | F9: - | G9: Positiva por amostra MUS; alternativos: contratos, recebimentos posteriores
A10: Advogados - litigios | B10: Nota 16 (p.60) | C10: 46822 | D10: Modelo C | E10: NAO ENVIADO (didatico) | F10: - | G10: Carta de advogados: provaveis (6.469) e possiveis (46.822)
A11: Partes relacionadas - saldos | B11: Nota 15 (p.59) | C11: 77302 | D11: Modelo D | E11: NAO ENVIADO (didatico) | F11: - | G11: Confirmacao com contraparte e contratos
A12: Terrenos a pagar | B12: BP (p.21-22) | C12: 64448 | D12: Modelo D | E12: NAO ENVIADO (didatico) | F12: - | G12: Contratos de compra e recibos
A14: Total do escopo planejado (R$ mil) | C14: =SUM(C5:C12) -> 5180546
A15: Obs.: total mistura saldos de ativo e passivo e exposicoes; nao representa cobertura percentual de uma demonstracao.
